<?xml version="1.0" ?>
<!-- =================================================================================== -->
<!-- |    This document was autogenerated by xacro from /home/shan/dev_ws/src/mohd_shan/description/robot_core.xacro | -->
<!-- |    EDITING THIS FILE BY HAND IS NOT RECOMMENDED                                 | -->
<!-- =================================================================================== -->
<robot name="hai_robot">
  <link name="base_link">
    <inertial>
      <origin rpy="0 0 0" xyz="0.000368761558726893 0.000222079211190218 -0.0186832943864639"/>
      <mass value="0.921963005425886"/>
      <inertia ixx="0.00268947436013833" ixy="-8.01568946641351E-06" ixz="8.59504316907562E-07" iyy="0.00489558963627434" iyz="1.75461888359984E-06" izz="0.00732819171596806"/>
    </inertial>
    <visual>
      <origin rpy="0 0 0" xyz="0 0 0"/>
      <geometry>
        <mesh filename="package://mohd_shan/meshes/base_link.STL"/>
      </geometry>
      <material name="">
        <color rgba="0.792156862745098 0.819607843137255 0.933333333333333 1"/>
      </material>
    </visual>
    <collision>
      <origin rpy="0 0 0" xyz="0 0 0"/>
      <geometry>
        <mesh filename="package://mohd_shan/meshes/base_link.STL"/>
      </geometry>
    </collision>
  </link>
  <link name="Link_BR">
    <inertial>
      <origin rpy="0 0 0" xyz="0 0.0074934 -2.2204E-16"/>
      <mass value="0.074247"/>
      <inertia ixx="3.0786E-05" ixy="1.9378E-19" ixz="3.8312E-21" iyy="5.884E-05" iyz="-2.0715E-19" izz="3.0786E-05"/>
    </inertial>
    <visual>
      <origin rpy="0 0 0" xyz="0 0 0"/>
      <geometry>
        <mesh filename="package://mohd_shan/meshes/Link_BR.STL"/>
      </geometry>
      <material name="">
        <color rgba="0.79216 0.81961 0.93333 1"/>
      </material>
    </visual>
    <collision>
      <origin rpy="0 0 0" xyz="0 0 0"/>
      <geometry>
        <mesh filename="package://mohd_shan/meshes/Link_BR.STL"/>
      </geometry>
    </collision>
  </link>
  <joint name="joint_BR" type="continuous">
    <origin rpy="0 0 0" xyz="-0.10018 -0.1126 -0.058355"/>
    <parent link="base_link"/>
    <child link="Link_BR"/>
    <axis xyz="0 1 0"/>
  </joint>
  <link name="Link_FR">
    <inertial>
      <origin rpy="0 0 0" xyz="1.1102E-16 0.0074934 -2.2204E-16"/>
      <mass value="0.074247"/>
      <inertia ixx="3.0786E-05" ixy="1.959E-19" ixz="-6.8527E-34" iyy="5.884E-05" iyz="-9.7951E-20" izz="3.0786E-05"/>
    </inertial>
    <visual>
      <origin rpy="0 0 0" xyz="0 0 0"/>
      <geometry>
        <mesh filename="package://mohd_shan/meshes/Link_FR.STL"/>
      </geometry>
      <material name="">
        <color rgba="0.79216 0.81961 0.93333 1"/>
      </material>
    </visual>
    <collision>
      <origin rpy="0 0 0" xyz="0 0 0"/>
      <geometry>
        <mesh filename="package://mohd_shan/meshes/Link_FR.STL"/>
      </geometry>
    </collision>
  </link>
  <joint name="joint_FR" type="continuous">
    <origin rpy="0 0 0" xyz="0.10018 -0.1126 -0.058355"/>
    <parent link="base_link"/>
    <child link="Link_FR"/>
    <axis xyz="0 1 0"/>
  </joint>
  <link name="Link_FL">
    <inertial>
      <origin rpy="0 0 0" xyz="1.1102E-16 -0.0074934 0"/>
      <mass value="0.074247"/>
      <inertia ixx="3.0786E-05" ixy="-3.6573E-20" ixz="-1.3332E-21" iyy="5.884E-05" iyz="2.2518E-19" izz="3.0786E-05"/>
    </inertial>
    <visual>
      <origin rpy="0 0 0" xyz="0 0 0"/>
      <geometry>
        <mesh filename="package://mohd_shan/meshes/Link_FL.STL"/>
      </geometry>
      <material name="">
        <color rgba="0.79216 0.81961 0.93333 1"/>
      </material>
    </visual>
    <collision>
      <origin rpy="0 0 0" xyz="0 0 0"/>
      <geometry>
        <mesh filename="package://mohd_shan/meshes/Link_FL.STL"/>
      </geometry>
    </collision>
  </link>
  <joint name="joint_FL" type="continuous">
    <origin rpy="0 0 0" xyz="0.10018 0.1126 -0.058355"/>
    <parent link="base_link"/>
    <child link="Link_FL"/>
    <axis xyz="0 1 0"/>
  </joint>
  <link name="Link_BL">
    <inertial>
      <origin rpy="0 0 0" xyz="-4.4409E-16 -0.0074934 -4.4409E-16"/>
      <mass value="0.074247"/>
      <inertia ixx="3.0786E-05" ixy="1.3418E-24" ixz="4.0908E-37" iyy="5.884E-05" iyz="-3.0264E-19" izz="3.0786E-05"/>
    </inertial>
    <visual>
      <origin rpy="0 0 0" xyz="0 0 0"/>
      <geometry>
        <mesh filename="package://mohd_shan/meshes/Link_BL.STL"/>
      </geometry>
      <material name="">
        <color rgba="0.79216 0.81961 0.93333 1"/>
      </material>
    </visual>
    <collision>
      <origin rpy="0 0 0" xyz="0 0 0"/>
      <geometry>
        <mesh filename="package://mohd_shan/meshes/Link_BL.STL"/>
      </geometry>
    </collision>
  </link>
  <joint name="joint_BL" type="continuous">
    <origin rpy="0 0 0" xyz="-0.10018 0.1126 -0.058355"/>
    <parent link="base_link"/>
    <child link="Link_BL"/>
    <axis xyz="0 1 0"/>
  </joint>
</robot>
